Workbook

Sheet Path to $50K
A1: Path to $50K Monthly Profit — Shutter
A2: How many creators, bookings, and users it takes to hit $50,000/month net (before taxes)
A4: KEY ASSUMPTIONS (blue = change these) | D4: All assumptions feed every table below
A5: Avg booking value ($) | B5: 1000 | C5: Conservative Tahoe rate — adjust up for multi-day shoots
A6: Client service fee % | B6: 0.08 | C6: Flat 8% platform service fee (Orchestrator Apr 20 ruling). Was 4% client + 2% creator before retirement.
A7: Creator payout deduction % | B7: 0 | C7: Retired Apr 20 — folded into unified 8% above. Left at 0 to preserve formula compatibility.
A8: Processor fee % (Stripe/Helcim) | B8: 0.029 | C8: 2.9% Stripe | 2.49% Helcim | 0% Dwolla ACH
A9: Processor fixed fee per txn ($) | B9: 0.3 | C9: $0.30 Stripe | $0.25 Helcim | ~$0.25 Dwolla
A10: Creator Pro monthly price ($) | B10: 14 | C10: Phase 2 trigger at 25 real creators; $14/mo per Apr 23 monetization roadmap (was $19).
A11: Creator Pro adoption rate % | B11: 0.65 | C11: % of active creators who pay for Pro
A12: Avg bookings per creator per month | B12: 3 | C12: Realistic mid-season average — adjust per season
A13: Infra cost per month ($) | B13: 300 | C13: Conservative Stage 2-3 estimate
A15: NET REVENUE PER BOOKING (auto-calculated from assumptions)
A16: Client pays (booking + service fee) | B16: =$B$5*(1+$B$6) -> 1080
A17: Processor fee on client total | B17: =B16*$B$8+$B$9 -> 31.62
A18: Creator payout (booking - deduction) | B18: =$B$5*(1-$B$7) -> 1000
A19: Platform gross (fees collected) | B19: =$B$5*$B$6+$B$5*$B$7 -> 80
A20: Platform NET per booking (after processor) | B20: =B17-B18-B19 -> -1048.38
A23: SCENARIOS — WHAT IT TAKES TO HIT $50K/MONTH
A24: Each scenario uses a different mix of creator count and booking volume. Change assumptions above to update.
A25: Scenario | B25: Active Creators | C25: Bookings/Month | D25: Transaction Revenue | E25: Pro Subscriptions | F25: Total Revenue | G25: Net Profit
A26: A — Tahoe Only (no subscriptions) | B26: 200 | C26: =$B$12*B26 -> 600 | D26: =C26*$B$20 -> -629028 | E26: =0 -> 0 | F26: =D26+E26 -> -629028 | G26: =F26-$B$13 -> -629328
A27: B — Tahoe + Reno (some Pro creators) | B27: 400 | C27: =$B$12*B27 -> 1200 | D27: =C27*$B$20 -> -1258056 | E27: =B27*$B$11*$B$10 -> 3640 | F27: =D27+E27 -> -1254416 | G27: =F27-$B$13 -> -1254716
A28: C — Tahoe+Reno+SF (Pro at scale) | B28: 600 | C28: =$B$12*B28 -> 1800 | D28: =C28*$B$20 -> -1887084 | E28: =B28*$B$11*$B$10 -> 5460 | F28: =D28+E28 -> -1881624 | G28: =F28-$B$13 -> -1881924
A29: D — Multi-market (full Pro adoption) | B29: 900 | C29: =$B$12*B29 -> 2700 | D29: =C29*$B$20 -> -2830626 | E29: =B29*$B$11*$B$10 -> 8190 | F29: =D29+E29 -> -2822436 | G29: =F29-$B$13 -> -2822736
A30: 🎯 TARGET: $50,000/month profit | G30: =50000 -> 50000
A32: REVERSE SOLVER — Exact user count needed for $50K/month
A33: Metric | B33: Transactions Only | C33: + Some Pro (65%) | D33: Notes
A34: Net per booking ($) | B34: =$B$20 -> -1048.38 | C34: =$B$20 -> -1048.38 | D34: Auto-calculated above
A35: Monthly Pro revenue at target | B35: =0 -> 0 | C35: =50000*0.2 -> 10000 | D35: Assume Pro covers 20% of target in mix scenario
A36: Bookings needed from txns | B36: =IFERROR(50000/B34,0) -> -47.692631 | C36: =IFERROR((50000-C35)/B34,0) -> -38.154104 | D36: Total bookings required
A37: Creators needed | B37: =IFERROR(B36/$B$12,0) -> -15.897544 | C37: =IFERROR(C36/$B$12,0) -> -12.718035 | D37: At avg bookings/creator assumption
A38: Creator Pro paying creators | B38: =0 -> 0 | C38: =IFERROR(C35/$B$10,0) -> 714.28571 | D38: Revenue ÷ Pro price
A39: Total creators on platform | B39: =B37 -> -15.897544 | C39: =MAX(C37,C38) -> 714.28571 | D39: Larger of needed for bookings vs Pro
A40: Clients (est. 8:1 ratio) | B40: =B39*8 -> -127.18035 | C40: =C39*8 -> 5714.2857 | D40: 8 clients per creator is realistic for local marketplace
A41: Total MAU (creators+clients) | B41: =B39+B40 -> -143.07789 | C41: =C39+C40 -> 6428.5714 | D41: Monthly active users estimate
A42: Expansion needed? | B42: =IF(B39>150,"Yes — expand markets","Tahoe only") -> Tahoe only | C42: =IF(C39>150,"Yes — expand markets","Tahoe only") -> Yes — expand markets | D42: Tahoe market realistically supports ~150 active creators
A46: MARKET EXPANSION ROADMAP TO $50K
A47: Phase | B47: Market | C47: Target Creators | D47: Target Bookings/mo | E47: Est. Monthly Revenue | F47: Cumulative Revenue | G47: Timeline
A48: Phase 1 | B48: Lake Tahoe / Truckee | C48: 25 | D48: =C48*$B$12 -> 75 | E48: =C48*$B$12*$B$20 -> -78628.5 | F48: =E48 -> -78628.5 | G48: Now → 6 mo
...

Sheet Dashboard
A1: SHUTTER — Financial Dashboard
A2: April 2026 | Stage 1: Pre-Revenue | Founder: Patrick Yun
A4: Monthly Infra Cost | B4: Annual LLC Tax | C4: Stripe per $1K | D4: Tax Reserve % | E4: Break-even Bookings
A5: =Infrastructure!B22 -> 9.5 | B5: ='Tax Planning'!C6 -> 800 | C5: ='Stripe Fees'!C8 -> 50.7 | D5: ='Tax Planning'!C20 -> 0.33 | E5: ='Revenue Model'!B42 -> 0.18737673
A6: (linked) | B6: (linked) | C6: (linked) | D6: (linked) | E6: (linked)
A8: STAGE OVERVIEW
A9: Stage | B9: Users | C9: Est. Monthly Cost | D9: Monthly Revenue | E9: Status | F9: Notes
A10: Stage 1 — Pre-Revenue | B10: 0 – 500 | C10: $0 – $20 | D10: $0 | E10: ✅ Current | F10: All services on free tiers. Only cost: Apple Dev $99/yr if pursuing App Store.
A11: Stage 2 — Early Traction | B11: 500 – 2,000 | C11: $65 – $150 | D11: $500 – $5K | E11: ⏳ Next | F11: Netlify Pro, Supabase Pro, Resend paid kick in.
A12: Stage 3 — Scale | B12: 2,000+ | C12: $300 – $500 | D12: $10K+ | E12: 🔮 Future | F12: Add accounting SW, bookkeeper, higher Mapbox usage.
A14: SHEET GUIDE
A15: Sheet | B15: Description
A16: Infrastructure | B16: Monthly & annual cost breakdown across all 3 stages
A17: Revenue Model | B17: Creator count + booking frequency → projected revenue (24 months)
A18: Refund Scenarios | B18: Partial-refund cash flow per Finance Apr 23 ruling (option a)
A19: P&L Taxonomy | B19: Chart of accounts for QuickBooks once Mercury opens
A21: APRIL 30 SNAPSHOT
A22: Mercury submission readiness | B22: BLOCKED — Patrick has not yet filed CA LLC-1 ($70, bizfileonline.sos.ca.gov)
A23: Year-1 no-revenue burn (low / high) | B23: =Runway!B17 -> 940 | C23: =Runway!C17 -> 2547
A24: Real creator count | B24: 0 / 7 seeded — Phase 2 ($14/mo Pro) triggers at 25
A25: Geo-ads launch gate | B25: 3 / 6 preconditions cleared (domain, Stripe webhook, Legal mark sign-off)
A26: Paid-media spend YTD | B26: $0 — gate not yet cleared. $500/mo cap when active.
A27: Mercury Pre-Stage | B27: Pre-staged Mercury application checklist + document timeline
A28: Runway | B28: Year-1 no-revenue burn ($2,000–$2,800), FTB timing, paid-media contingency

Sheet Infrastructure
A1: Infrastructure & Operating Costs
A2: Blue = input (change these) | Black = formula | All costs in USD
A3: Service | B3: Monthly Cost ($) | C3: Frequency | D3: Annual Cost ($) | E3: Notes
A4: STAGE 1 — Pre-Revenue (0–500 users)
A5: Netlify | B5: 0 | C5: monthly | D5: =B5*12 -> 0 | E5: Free tier (100GB BW, 300 build min)
A6: Supabase | B6: 0 | C6: monthly | D6: =B6*12 -> 0 | E6: Free tier (500MB DB, 1GB storage, 50k auth users)
A7: Mapbox | B7: 0 | C7: monthly | D7: =B7*12 -> 0 | E7: Free tier (50k map loads/mo)
A8: Resend | B8: 0 | C8: monthly | D8: =B8*12 -> 0 | E8: Free tier (100 emails/day)
A9: Apple Dev | B9: 8.25 | C9: monthly | D9: =B9*12 -> 99 | E9: $99/yr — only if pursuing App Store
A10: Domain (est.) | B10: 1.25 | C10: monthly | D10: =B10*12 -> 15 | E10: ~$15/yr at Namecheap/Cloudflare — after brand name locked
A11: STAGE 1 TOTAL | B11: =SUM(B5:B10) -> 9.5 | D11: =SUM(D5:D10) -> 114 | E11: Source: Netlify/Supabase/Mapbox/Resend pricing pages, April 2026
A13: STAGE 2 — Early Traction (500–2,000 users)
A14: Netlify Pro | B14: 19 | C14: monthly | D14: =B14*12 -> 228 | E14: $19/mo — custom domain, analytics, more bandwidth
A15: Supabase Pro | B15: 25 | C15: monthly | D15: =B15*12 -> 300 | E15: $25/mo — hits at ~500MB storage from portfolio photos
A16: Mapbox | B16: 10 | C16: monthly | D16: =B16*12 -> 120 | E16: Est. $10/mo at moderate traffic (above 50k loads)
A17: Resend | B17: 20 | C17: monthly | D17: =B17*12 -> 240 | E17: $20/mo — up to 50k emails
A18: Apple Dev | B18: 8.25 | C18: monthly | D18: =B18*12 -> 99 | E18: $99/yr — App Store
A19: Domain | B19: 1.25 | C19: monthly | D19: =B19*12 -> 15 | E19: ~$15/yr
A20: Misc / Buffer | B20: 15 | C20: monthly | D20: =B20*12 -> 180 | E20: SMS, monitoring, small tools
A21: STAGE 2 TOTAL | B21: =SUM(B14:B20) -> 98.5 | D21: =SUM(D14:D20) -> 1182 | E21: Source: Netlify/Supabase pricing pages, April 2026
B22: =B11 -> 9.5
A23: STAGE 3 — Scale (2,000+ users, $10K+/mo revenue)
A24: Netlify Business | B24: 99 | C24: monthly | D24: =B24*12 -> 1188 | E24: $99/mo — team access, higher limits
A25: Supabase Pro | B25: 25 | C25: monthly | D25: =B25*12 -> 300 | E25: $25/mo + usage overage
A26: Mapbox | B26: 100 | C26: monthly | D26: =B26*12 -> 1200 | E26: Est. $100/mo at high traffic
A27: Resend | B27: 20 | C27: monthly | D27: =B27*12 -> 240 | E27: $20/mo
A28: Apple Dev | B28: 8.25 | C28: monthly | D28: =B28*12 -> 99 | E28: $99/yr
A29: Domain | B29: 1.25 | C29: monthly | D29: =B29*12 -> 15 | E29: ~$15/yr
A30: Accounting SW | B30: 15 | C30: monthly | D30: =B30*12 -> 180 | E30: QuickBooks Self-Employed
A31: Bookkeeper | B31: 300 | C31: monthly | D31: =B31*12 -> 3600 | E31: Part-time bookkeeper at scale
A32: Legal / CPA | B32: 83 | C32: monthly | D32: =B32*12 -> 996 | E32: ~$1K/yr for annual tax prep
A33: Misc / Buffer | B33: 50 | C33: monthly | D33: =B33*12 -> 600 | E33: Monitoring, ops tools, misc
A34: STAGE 3 TOTAL | B34: =SUM(B24:B33) -> 701.5 | D34: =SUM(D24:D33) -> 8418

Sheet Revenue Model
A1: Revenue Model — 24-Month Projection
A3: ASSUMPTIONS (blue = change these)
A4: Average booking value ($) | B4: 1000
A5: Platform commission rate (%) | B5: 0.08
A6: Stripe fee rate (%) | B6: 0.029
A7: Stripe fixed fee per txn ($) | B7: 0.3
A8: Creators at Month 1 | B8: 7
A9: New creators added per month | B9: 2
A10: Bookings per creator per month | B10: 0.5
A12: MONTHLY PROJECTIONS
A13: Month | B13: Creators | C13: Total Bookings | D13: Gross Volume ($) | E13: Commission ($) | F13: Stripe Fees ($) | G13: Net Revenue ($)
A14: 1 | B14: =$B$8 -> 7 | C14: =B14*$B$10 -> 3.5 | D14: =C14*$B$4 -> 3500 | E14: =D14*$B$5 -> 280 | F14: =D14*$B$6+C14*$B$7 -> 102.55 | G14: =E14-F14 -> 177.45
A15: 2 | B15: =B14+$B$9 -> 9 | C15: =B15*$B$10 -> 4.5 | D15: =C15*$B$4 -> 4500 | E15: =D15*$B$5 -> 360 | F15: =D15*$B$6+C15*$B$7 -> 131.85 | G15: =E15-F15 -> 228.15
A16: 3 | B16: =B15+$B$9 -> 11 | C16: =B16*$B$10 -> 5.5 | D16: =C16*$B$4 -> 5500 | E16: =D16*$B$5 -> 440 | F16: =D16*$B$6+C16*$B$7 -> 161.15 | G16: =E16-F16 -> 278.85
A17: 4 | B17: =B16+$B$9 -> 13 | C17: =B17*$B$10 -> 6.5 | D17: =C17*$B$4 -> 6500 | E17: =D17*$B$5 -> 520 | F17: =D17*$B$6+C17*$B$7 -> 190.45 | G17: =E17-F17 -> 329.55
A18: 5 | B18: =B17+$B$9 -> 15 | C18: =B18*$B$10 -> 7.5 | D18: =C18*$B$4 -> 7500 | E18: =D18*$B$5 -> 600 | F18: =D18*$B$6+C18*$B$7 -> 219.75 | G18: =E18-F18 -> 380.25
A19: 6 | B19: =B18+$B$9 -> 17 | C19: =B19*$B$10 -> 8.5 | D19: =C19*$B$4 -> 8500 | E19: =D19*$B$5 -> 680 | F19: =D19*$B$6+C19*$B$7 -> 249.05 | G19: =E19-F19 -> 430.95
A20: 7 | B20: =B19+$B$9 -> 19 | C20: =B20*$B$10 -> 9.5 | D20: =C20*$B$4 -> 9500 | E20: =D20*$B$5 -> 760 | F20: =D20*$B$6+C20*$B$7 -> 278.35 | G20: =E20-F20 -> 481.65
A21: 8 | B21: =B20+$B$9 -> 21 | C21: =B21*$B$10 -> 10.5 | D21: =C21*$B$4 -> 10500 | E21: =D21*$B$5 -> 840 | F21: =D21*$B$6+C21*$B$7 -> 307.65 | G21: =E21-F21 -> 532.35
A22: 9 | B22: =B21+$B$9 -> 23 | C22: =B22*$B$10 -> 11.5 | D22: =C22*$B$4 -> 11500 | E22: =D22*$B$5 -> 920 | F22: =D22*$B$6+C22*$B$7 -> 336.95 | G22: =E22-F22 -> 583.05
A23: 10 | B23: =B22+$B$9 -> 25 | C23: =B23*$B$10 -> 12.5 | D23: =C23*$B$4 -> 12500 | E23: =D23*$B$5 -> 1000 | F23: =D23*$B$6+C23*$B$7 -> 366.25 | G23: =E23-F23 -> 633.75
A24: 11 | B24: =B23+$B$9 -> 27 | C24: =B24*$B$10 -> 13.5 | D24: =C24*$B$4 -> 13500 | E24: =D24*$B$5 -> 1080 | F24: =D24*$B$6+C24*$B$7 -> 395.55 | G24: =E24-F24 -> 684.45
A25: 12 | B25: =B24+$B$9 -> 29 | C25: =B25*$B$10 -> 14.5 | D25: =C25*$B$4 -> 14500 | E25: =D25*$B$5 -> 1160 | F25: =D25*$B$6+C25*$B$7 -> 424.85 | G25: =E25-F25 -> 735.15
A26: 13 | B26: =B25+$B$9 -> 31 | C26: =B26*$B$10 -> 15.5 | D26: =C26*$B$4 -> 15500 | E26: =D26*$B$5 -> 1240 | F26: =D26*$B$6+C26*$B$7 -> 454.15 | G26: =E26-F26 -> 785.85
... A37: 24 | B37: =B36+$B$9 -> 53 | C37: =B37*$B$10 -> 26.5 | D37: =C37*$B$4 -> 26500 | E37: =D37*$B$5 -> 2120 | F37: =D37*$B$6+C37*$B$7 -> 776.45 | G37: =E37-F37 -> 1343.55
A38: 24-MONTH TOTAL | C38: =SUM(C14:C37) -> 360 | D38: =SUM(D14:D37) -> 360000 | E38: =SUM(E14:E37) -> 28800 | F38: =SUM(F14:F37) -> 10548 | G38: =SUM(G14:G37) -> 18252
A42: Break-even bookings needed (monthly) | B42: =IFERROR((Infrastructure!B11)/($B$4*$B$5-$B$4*$B$6-$B$7), 0) -> 0.18737673

Sheet Stripe Fees
A1: Stripe Fee Analysis — Net Revenue per Booking
A2: Shows your actual net on each booking size after Stripe takes their 2.9% + $0.30
A4: STRIPE ASSUMPTIONS
A5: Stripe % fee | B5: 0.029 | C5: 0.029
A6: Stripe fixed fee ($) | B6: 0.3
A7: Your commission % | B7: 0.08
C8: =F14 -> 50.7
A9: Booking Size ($) | B9: Gross Commission | C9: Stripe % Fee | D9: Stripe Fixed | E9: Total Stripe Cost | F9: Your Net Revenue | G9: Effective Net Rate
A10: 200 | B10: =A10*$B$7 -> 16 | C10: =A10*$B$5 -> 5.8 | D10: =$B$6 -> 0.3 | E10: =C10+D10 -> 6.1 | F10: =B10-E10 -> 9.9 | G10: =IFERROR(F10/A10,0) -> 0.0495
A11: 350 | B11: =A11*$B$7 -> 28 | C11: =A11*$B$5 -> 10.15 | D11: =$B$6 -> 0.3 | E11: =C11+D11 -> 10.45 | F11: =B11-E11 -> 17.55 | G11: =IFERROR(F11/A11,0) -> 0.050142857
A12: 500 | B12: =A12*$B$7 -> 40 | C12: =A12*$B$5 -> 14.5 | D12: =$B$6 -> 0.3 | E12: =C12+D12 -> 14.8 | F12: =B12-E12 -> 25.2 | G12: =IFERROR(F12/A12,0) -> 0.0504
A13: 750 | B13: =A13*$B$7 -> 60 | C13: =A13*$B$5 -> 21.75 | D13: =$B$6 -> 0.3 | E13: =C13+D13 -> 22.05 | F13: =B13-E13 -> 37.95 | G13: =IFERROR(F13/A13,0) -> 0.0506
A14: 1000 | B14: =A14*$B$7 -> 80 | C14: =A14*$B$5 -> 29 | D14: =$B$6 -> 0.3 | E14: =C14+D14 -> 29.3 | F14: =B14-E14 -> 50.7 | G14: =IFERROR(F14/A14,0) -> 0.0507
A15: 1250 | B15: =A15*$B$7 -> 100 | C15: =A15*$B$5 -> 36.25 | D15: =$B$6 -> 0.3 | E15: =C15+D15 -> 36.55 | F15: =B15-E15 -> 63.45 | G15: =IFERROR(F15/A15,0) -> 0.05076
A16: 1500 | B16: =A16*$B$7 -> 120 | C16: =A16*$B$5 -> 43.5 | D16: =$B$6 -> 0.3 | E16: =C16+D16 -> 43.8 | F16: =B16-E16 -> 76.2 | G16: =IFERROR(F16/A16,0) -> 0.0508
A17: 2000 | B17: =A17*$B$7 -> 160 | C17: =A17*$B$5 -> 58 | D17: =$B$6 -> 0.3 | E17: =C17+D17 -> 58.3 | F17: =B17-E17 -> 101.7 | G17: =IFERROR(F17/A17,0) -> 0.05085
A18: 2500 | B18: =A18*$B$7 -> 200 | C18: =A18*$B$5 -> 72.5 | D18: =$B$6 -> 0.3 | E18: =C18+D18 -> 72.8 | F18: =B18-E18 -> 127.2 | G18: =IFERROR(F18/A18,0) -> 0.05088
A19: 3000 | B19: =A19*$B$7 -> 240 | C19: =A19*$B$5 -> 87 | D19: =$B$6 -> 0.3 | E19: =C19+D19 -> 87.3 | F19: =B19-E19 -> 152.7 | G19: =IFERROR(F19/A19,0) -> 0.0509
A21: Note: Stripe fee is applied to the full booking amount (not just your commission). Adjust the commission % assumption to model split-fee pricing (charging both creator and client).

Sheet Tax Planning
A1: Tax Planning — California LLC / Sole Founder
A2: Not financial/tax advice. Consult a CPA for your specific situation.
A4: FIXED ANNUAL TAXES (due regardless of revenue)
A5: CA LLC Minimum Franchise Tax | B5: 800 | C5: Due annually | D5: Source: CA FTB Form 3522. Due 15th day of 4th month after formation. AB 85 waiver EXPIRED for 2024+ formations (Legal Apr 21) — $800 due year 1.
A6: Apple Developer Account | B6: 99 | C6: =B5 -> 800 | D6: Only if pursuing App Store. Source: developer.apple.com
A8: REVENUE-BASED TAX RATES (assumptions)
A9: Self-employment tax rate | B9: 0.153 | D9: 15.3% on net profit (Social Security + Medicare)
A10: CA state income tax rate (est.) | B10: 0.093 | D10: 9.3% — typical bracket for small biz income in CA
A11: Federal income tax rate (est.) | B11: 0.22 | D11: 22% bracket — adjust based on total income
A12: Recommended total tax reserve % | B12: 0.33 | D12: Rule of thumb: set aside 33% of all platform revenue
A14: TAX CALCULATOR — Enter Your Monthly Net Revenue
A15: Monthly net platform revenue ($) | B15: 2000 | D15: Change this to model different revenue levels
A16: Annual net platform revenue ($) | B16: =B15*12 -> 24000
A17: CA LLC Franchise Tax (annual) | B17: =$B$5 -> 800
A18: Self-employment tax (annual) | B18: =B16*$B$9 -> 3672
A19: CA state income tax (annual, est.) | B19: =B16*$B$10 -> 2232
A20: Federal income tax (annual, est.) | B20: =B16*$B$11 -> 5280 | C20: =B12 -> 0.33
A21: TOTAL ANNUAL TAX ESTIMATE | B21: =SUM(B17:B20) -> 11984
A22: Monthly tax reserve needed | B22: =B21/12 -> 998.66667
A23: Tax as % of revenue (check) | B23: =IFERROR(B21/B16,0) -> 0.49933333
A25: QUARTERLY ESTIMATED TAX PAYMENTS
A26: Quarterly payment (÷4) | B26: =B21/4 -> 2996 | D26: Due: Apr 15 / Jun 15 / Sep 15 / Jan 15
A27: Q1 (Jan–Mar) | B27: =$B$26 -> 2996 | C27: Due: Apr 15
A28: Q2 (Apr–Jun) | B28: =$B$26 -> 2996 | C28: Due: Jun 15
A29: Q3 (Jul–Sep) | B29: =$B$26 -> 2996 | C29: Due: Sep 15
A30: Q4 (Oct–Dec) | B30: =$B$26 -> 2996 | C30: Due: Jan 15
A32: CA YEAR-1 STATE COST (per Legal Apr 21 + Finance Apr 23)
A33: LLC-1 filing fee | B33: 70 | D33: Source: bizfileonline.sos.ca.gov, online filing only since 2025
A34: LLC-12 Statement of Information | B34: 20 | D34: Due within 90 days of formation
A35: FTB $800 minimum franchise tax (year 1) | B35: 800 | D35: AB 85 EXPIRED. Form 3522. Due 15th day of 4th month after formation (~Aug 2026 if files May 2026).
A36: CA YEAR-1 TOTAL | B36: =SUM(B33:B35) -> 890

Sheet Creator Pro
A1: Creator Pro — Phase 2 Subscription Model
A2: When to launch: after 25 real creators. What Pro unlocks for paying creators.
A4: CREATOR PRO PERKS (what paying creators get)
A5: Perk | B5: Description
A6: Featured map placement | B6: Pin appears above non-Pro creators in the same area
A7: Verified badge | B7: Purple ✓ shown on pin and profile card — builds trust with clients
A8: Priority in search/filter | B8: Shows first when clients filter by discipline
A9: Analytics dashboard | B9: View count trends, booking conversion rate, profile views over time
A10: Booking protection | B10: Payment guaranteed even if client cancels within 24hrs
A11: Rate card PDF export | B11: Generate a shareable rate card to send to clients directly
A13: PRICING TIERS — ASSUMPTIONS (blue = change)
A14: Tier | B14: Price/Month | C14: Annual (÷12) | D14: Target Creators | E14: Monthly Revenue | F14: Notes
A15: Pro Monthly | B15: 14 | C15: =B15 -> 14 | D15: 50 | E15: =B15*D15 -> 700 | F15: Pro Monthly $14/mo per Apr 23 monetization roadmap. Phase 2 trigger at 25 real creators.
A16: Pro Annual | B16: 11 | C16: =B16 -> 11 | D16: 30 | E16: =B16*D16 -> 330 | F16: Pro Annual $11/mo billed yearly = $132/yr; saves $36 vs $14×12.
A17: Pro Founding | B17: 9 | C17: =B17 -> 9 | D17: 20 | E17: =B17*D17 -> 180 | F17: Pro Founding $9/mo grandfathered for first 25 real creators. Lock for life.
A18: TOTAL PRO MONTHLY REVENUE | E18: =SUM(E15:E17) -> 1210
A20: LAUNCH SEQUENCE
A21: Step | B21: Action | C21: Detail
A22: Step 1 | B22: Reach 25 real creators | C22: Free phase — grow the map. No monetization.
A23: Step 2 | B23: Soft launch Creator Pro | C23: Email first 25 creators. Offer Founding rate ($12/mo) to early adopters. No pressure.
A24: Step 3 | B24: Announce Pro publicly | C24: TikTok/Reels post showing the verified badge and featured placement. Make it feel exclusive.
A25: Step 4 | B25: New creators default to Pro trial | C25: 14-day free Pro trial for every new creator who joins. Most will stay.
A26: Step 5 | B26: Raise price for new creators | C26: After 6 months: new creators pay $19/mo. Founding creators keep $12/mo forever.

Sheet Processor Comparison
A1: Payment Processor Comparison — Find Cheapest Option for Shutter
A2: Lower processor fees = more profit per booking. Sources: official pricing pages, April 2026.
A4: PROCESSOR RATES
A5: Processor | B5: Rate % | C5: Fixed Fee | D5: Cards? | E5: ACH? | F5: Marketplace? | G5: Notes
A6: Stripe Connect | B6: 0.029 | C6: 0.3 | D6: ✅ Yes | E6: ✅ Yes ($1.50) | F6: ✅ Best-in-class | G6: Industry standard. Best developer tools & Connect API for marketplace payouts. Recommended for launch.
A7: Helcim | B7: 0.0249 | C7: 0.25 | D7: ✅ Yes | E7: ✅ Yes | F7: ⚠️ Manual setup | G7: Interchange+ pricing. Avg 25% cheaper than Stripe at volume. Less mature marketplace API.
A8: Braintree (PayPal) | B8: 0.0259 | C8: 0.49 | D8: ✅ Yes | E8: ❌ Limited | F8: ✅ Yes | G8: 2.59% + $0.49 per card. BUT 0.75% flat for ACH bank transfers — huge savings on large bookings. No monthly fees. Note: $50K free promotion was discontinued in 2016.
A9: Dwolla (ACH only) | B9: 0 | C9: 0 | D9: ❌ No | E9: ✅ Cheapest | F9: ✅ Yes | G9: ACH bank transfers only — no credit cards. Usage-based pricing, contact for quote. ~$0.25-$1 per txn. Best for large bookings.
A10: PayPal Payouts | B10: 0.0349 | C10: 0.49 | D10: ✅ Yes | E10: ❌ | F10: ⚠️ Limited | G10: Most expensive option. 3.49% + $0.49. Not recommended.
A11: Square | B11: 0.029 | C11: 0.3 | D11: ✅ Yes | E11: ❌ | F11: ❌ No marketplace | G11: Same rate as Stripe but no marketplace/Connect equivalent. Not suitable for Shutter.
A13: COST COMPARISON BY BOOKING SIZE — What each processor costs you per transaction
A14: Booking Size | B14: Stripe | C14: Helcim | D14: Braintree* | E14: Dwolla ACH | F14: Savings vs Stripe (Helcim) | G14: Best Choice
A15: 200 | B15: =A15*0.029+0.3 -> 6.1 | C15: =A15*0.0249+0.25 -> 5.23 | D15: =A15*0.0259+0.49 -> 5.67 | E15: =MIN(A15*0.005,5)+0.25 -> 1.25 | F15: =B15-C15 -> 0.87 | G15: =IF(A15<500,"Stripe (simplicity)","Helcim or Dwolla ACH") -> Stripe (simplicity)
A16: 500 | B16: =A16*0.029+0.3 -> 14.8 | C16: =A16*0.0249+0.25 -> 12.7 | D16: =A16*0.0259+0.49 -> 13.44 | E16: =MIN(A16*0.005,5)+0.25 -> 2.75 | F16: =B16-C16 -> 2.1 | G16: =IF(A16<500,"Stripe (simplicity)","Helcim or Dwolla ACH") -> Helcim or Dwolla ACH
A17: 750 | B17: =A17*0.029+0.3 -> 22.05 | C17: =A17*0.0249+0.25 -> 18.925 | D17: =A17*0.0259+0.49 -> 19.915 | E17: =MIN(A17*0.005,5)+0.25 -> 4 | F17: =B17-C17 -> 3.125 | G17: =IF(A17<500,"Stripe (simplicity)","Helcim or Dwolla ACH") -> Helcim or Dwolla ACH
A18: 1000 | B18: =A18*0.029+0.3 -> 29.3 | C18: =A18*0.0249+0.25 -> 25.15 | D18: =A18*0.0259+0.49 -> 26.39 | E18: =MIN(A18*0.005,5)+0.25 -> 5.25 | F18: =B18-C18 -> 4.15 | G18: =IF(A18<500,"Stripe (simplicity)","Helcim or Dwolla ACH") -> Helcim or Dwolla ACH
A19: 1500 | B19: =A19*0.029+0.3 -> 43.8 | C19: =A19*0.0249+0.25 -> 37.6 | D19: =A19*0.0259+0.49 -> 39.34 | E19: =MIN(A19*0.005,5)+0.25 -> 5.25 | F19: =B19-C19 -> 6.2 | G19: =IF(A19<500,"Stripe (simplicity)","Helcim or Dwolla ACH") -> Helcim or Dwolla ACH
A20: 2000 | B20: =A20*0.029+0.3 -> 58.3 | C20: =A20*0.0249+0.25 -> 50.05 | D20: =A20*0.0259+0.49 -> 52.29 | E20: =MIN(A20*0.005,5)+0.25 -> 5.25 | F20: =B20-C20 -> 8.25 | G20: =IF(A20<500,"Stripe (simplicity)","Helcim or Dwolla ACH") -> Helcim or Dwolla ACH
A21: 2500 | B21: =A21*0.029+0.3 -> 72.8 | C21: =A21*0.0249+0.25 -> 62.5 | D21: =A21*0.0259+0.49 -> 65.24 | E21: =MIN(A21*0.005,5)+0.25 -> 5.25 | F21: =B21-C21 -> 10.3 | G21: =IF(A21<500,"Stripe (simplicity)","Helcim or Dwolla ACH") -> Helcim or Dwolla ACH
A23: RECOMMENDATION FOR SHUTTER
A24: Stage | B24: Processor | C24: Reason
A25: 🚀 Launch (now) | B25: Stripe Connect | C25: Best docs, best marketplace API, easiest to implement. Worth the cost at low volume.
A26: 📈 Early traction | B26: Braintree | C26: 2.59% + $0.49 per card — slightly cheaper than Stripe at scale. Its ACH rate (0.75% flat) is excellent for large bookings. Consider offering ACH as a payment option.
A27: 💰 Scale ($5K+/mo txns) | B27: Helcim + Dwolla ACH | C27: Offer bank transfer (ACH via Dwolla) as a cheaper option for large bookings. Creators doing $1,500+ shoots save ~$30/booking by paying via ACH.
A28: 🎯 Long-term | B28: Negotiate with Adyen | C28: At $1M+/year in processing, Adyen offers interchange++ pricing well below 2%. Requires enterprise contract.
A30: ⚠️ Correction: Braintree's $50K free processing promotion ("Ignition") was discontinued in November 2016 and is no longer available. Current Braintree rates: 2.59% + $0.49 (cards), 0.75% (ACH). Source: helloari.com/blog, techcrunch.com/2012, April 2026.

Sheet Refund Scenarios
A1: Partial-Refund Cash Flow — Option (a) Ruling (Finance Apr 23)
A2: Platform retains 100% of 8% service fee on consummated bookings; refund deducted from client share only.
A3: Aligns with Stripe API: cancel-booking Edge Function ships in prompt v3 (Dev Apr 29).
A5: ASSUMPTIONS (blue = change)
A6: Original booking ($) | B6: 400 | C6: Edit to model different booking sizes
A7: Platform service fee % | B7: 0.08 | C7: 8% flat (Orchestrator Apr 20 ruling, locked)
A9: Tier | B9: Refund % | C9: Refund $ | D9: Creator earns | E9: Platform earns | F9: Client out-of-pocket | G9: Stripe API call
A10: 72h+ before shoot — full refund | B10: 1 | C10: =B6*B10 -> 400 | D10: 0 | E10: 0 | F10: =B6-C10 -> 0 | G10: refund_application_fee=true + reverse_transfer=true
A11: 24–72h before shoot — 50% refund | B11: 0.5 | C11: =B6*B11 -> 200 | D11: =(B6-C11)*(1-B7) -> 184 | E11: =(B6-C11)*B7 -> 16 | F11: =B6-C11 -> 200 | G11: refund_application_fee=false (platform keeps full fee)
A12: <24h before shoot — no refund | B12: 0 | C12: =B6*B12 -> 0 | D12: =B6*(1-B7) -> 368 | E12: =B6*B7 -> 32 | F12: =B6-C12 -> 400 | G12: No Stripe call. status = cancelled_no_refund
A13: Weather (14-day reschedule hold) | B13: 0 | C13: 0 | D13: =B6*(1-B7) -> 368 | E13: =B6*B7 -> 32 | F13: 0 | G13: No refund fires. If window expires → auto-convert to 50% tier.
A15: KEY NOTES
A16: • Bookings.amount_total in DB is stored in DOLLARS, not cents (Apr 29 schema gotcha). cancel-booking converts to cents before stripe.refunds.create.
A17: • Platform_fee_remaining column tracks the earned fee post partial-refund for QuickBooks reconciliation.
A18: • Stripe processing fees (2.9% + $0.30) are non-refundable from Stripe regardless of tier and are paid out of client charge at time of capture.
A19: • Industry precedent: Airbnb / GetYourGuide / Peerspace all retain platform cut on late cancellations. Defensible under CA Civ. Code § 1671(b) per Legal Apr 28.
A20: • TOS disclosure (approved by Orchestrator Apr 27, validated by Legal Apr 28): "Cancellations 24–72h before a shoot receive a 50% refund of the creator's share; the platform service fee is non-refundable once a booking has been accepted."

Sheet P&L Taxonomy
A1: P&L Taxonomy for QuickBooks (post-Mercury onboarding)
A2: Apply once Mercury → QuickBooks is connected. Pre-spec so tags are consistent from the first transaction.
A4: INCOME ACCOUNTS
A5: Account tag | B5: Description | C5: When it triggers
A6: revenue.platform_fee | B6: 8% service fee earned on completed bookings | C6: Phase 1 onward (live in code Apr 20)
A7: revenue.platform_fee.retained_from_refund | B7: Fee portion retained after partial refunds (24–72h tier) | C7: cancel-booking ships in prompt v3 (Dev Apr 29)
A8: revenue.creator_pro_subscription | B8: $14/mo Creator Pro (Phase 2) | C8: Trigger: 25 real creators
A9: revenue.gig_boost | B9: Phase 2+ paid gig-promotion lever | C9: Phase 2 — TBD
A10: revenue.brand_partnership | B10: Phase 3+ resort/brand sponsored spotlights | C10: Phase 3 — Palisades/Heavenly/Northstar
A13: EXPENSE ACCOUNTS
A14: Account tag | B14: Description | C14: When it triggers
A15: cost_of_revenue.stripe_fees | B15: Stripe 2.9% + $0.30 processing cost (passed through, tracked for margin) | C15: Every paid booking
A16: cost_of_revenue.stripe_connect_payout_fee | B16: Express payout fee (0.25% + $0.25 per payout) | C16: Every creator payout
A17: opex.infra.hosting | B17: Netlify | C17: Free tier through ~100 creators
A18: opex.infra.backend | B18: Supabase | C18: Free tier through ~50k MAU
A19: opex.infra.email | B19: Resend | C19: Free tier <3k emails/mo. Domain shutterfind.app verified Apr 29
A20: opex.infra.mapping | B20: Mapbox | C20: Free tier <50k loads/mo
A21: opex.software.accounting | B21: QuickBooks subscription (if paid tier needed) | C21: Defer until Mercury connected
A22: opex.legal_and_compliance.llc_filings | B22: LLC-1, LLC-12, registered agent | C22: $70 + $20 + ($0 self / $125 NW)
A23: opex.legal_and_compliance.trademark | B23: USPTO fees, comp. search | C23: DEFERRED per Patrick Apr 21
A24: opex.legal_and_compliance.franchise_tax | B24: CA $800 annual (FTB Form 3522) | C24: AB 85 EXPIRED. Year-1 ~Aug 15 if LLC files May
A25: opex.insurance | B25: GL + E&O | C25: Recommend before first real booking (~$30–60/mo)
... A32: opex.founder_draw | B32: Non-deductible owner distribution (tracked separately) | C32: Reconcile per quarter
A35: MERCURY SUB-ACCOUNTS → QuickBooks class mapping
A36: Mercury sub-account | B36: Purpose | C36: QB class
A37: Mercury:operating | B37: Day-to-day cash, default class | C37: Operating
A38: Mercury:taxes_reserve | B38: 30% of platform-fee income set aside for federal + CA pass-through | C38: TaxReserve
A39: Mercury:paid_media | B39: $500/mo paid-media ceiling, debit-card spend cap enforced | C39: PaidMedia
A40: Mercury:legal_filing_reserve | B40: $800 FTB set-aside (year 1 due Aug 2026 if files May) | C40: LegalReserve

Sheet Mercury Pre-Stage
A1: Mercury Application — Pre-Stage Checklist
A2: Status as of April 30, 2026: BLOCKED on Patrick filing CA LLC-1.
A3: Submit-target: same-day after Patrick lands stamped Articles of Organization + EIN (CP 575).
A5: PRE-POPULATED APPLICATION FIELDS
A6: Field | B6: Value | C6: Source / Note
A7: Legal business name | B7: Shutter Find LLC | C7: Orchestrator ruling Apr 16
A8: DBA / trade name | B8: Shutter | C8: Orchestrator ruling Apr 16
A9: Entity type | B9: LLC — single-member | C9: Legal Apr 21
A10: State of formation | B10: California | C10: Legal Apr 21
A11: EIN | B11: PENDING — Patrick to retrieve from irs.gov/ein after LLC cert | C11: Legal checklist
A12: Business address | B12: Patrick Yun — Truckee, CA (private; not stored in brain) | C12: Personal data
A13: Mailing address | B13: Same as business | C13: —
A14: Industry classification | B14: Online marketplaces (use this dropdown value) | C14: Finance recommendation
A15: Business description | B15: Map-first online marketplace connecting clients with freelance outdoor-sports photographers, videographers, drone operators, and models. Revenue model: 8% platform service fee on completed bookings via Stripe Connect Express. Launch beachhead Lake Tahoe; expansion to other US mountain and surf towns Phase 2+. | C15: Finance — Apr 30 update reflects mountain/surf scope per Patrick Apr 29
A16: Estimated monthly revenue | B16: $0 for first 60 days; scale per creator-count gates | C16: Finance
A17: Estimated monthly transactions | B17: 0–5 first 30 days; 10–25 MoM 60–90 days post-ads | C17: Finance
... A23: Business website | B23: https://shutterfind.app | C23: Domain registered Apr 29; HTTPS live
A26: DOCUMENTS REQUIRED AT SUBMISSION
A27: Document | B27: Status (Apr 30) | C27: Notes
A28: Stamped Articles of Organization (Form LLC-1) | B28: ⏳ BLOCKED — Patrick has not yet filed LLC-1 | C28: bizfileonline.sos.ca.gov, $70, ~5 biz day approval
A29: EIN Letter (IRS Form CP 575) | B29: ⏳ BLOCKED — pending LLC cert | C29: irs.gov/ein, free, instant after LLC issues
A30: Signed Operating Agreement | B30: 🟡 Template ready — Patrick to fill 5 fields + sign | C30: legal/ShutterFind_Operating_Agreement_template.md
A31: Patrick's government-issued photo ID | B31: ✅ On hand | C31: —
A32: Proof of business address | B32: ✅ On hand if needed (utility bill / lease) | C32: Only if business address ≠ ID address
A35: ESTIMATED SUBMISSION TIMELINE
A36: Step | B36: Days from Patrick filing LLC-1 | C36: Owner
A37: Patrick files LLC-1 online (BizFile) | B37: Day 0 | C37: Patrick
A38: California SOS approves Articles | B38: ~Day 5 (biz) | C38: CA SOS
A39: Patrick applies for EIN at irs.gov/ein | B39: Same day as approval | C39: Patrick
A40: Patrick signs Operating Agreement | B40: Same day | C40: Patrick
A41: Finance Agent submits Mercury application | B41: Day 5–6 | C41: Finance
A42: Mercury approval + account/routing issued | B42: Day 7–9 | C42: Mercury
A43: Mercury debit card ships | B43: Day 12–15 | C43: Mercury
A44: Stripe Connect platform-fee payout target wired up | B44: Day 8 (after approval) | C44: Finance + Dev

Sheet Runway
A1: Year-1 Pre-Revenue Runway (Apr 30 refresh)
A2: Absorbs AB 85 correction (Legal Apr 21) + $30 sticker print (Marketing Apr 29). All values in USD.
A4: CATEGORY | B4: Low ($) | C4: High ($) | D4: Notes
A5: CA LLC + franchise tax + SOI | B5: 890 | C5: 890 | D5: Fixed: $70 LLC-1 + $20 LLC-12 + $800 FTB. AB 85 EXPIRED.
A6: USPTO TEAS Plus (2 classes) | B6: 0 | C6: 500 | D6: DEFERRED per Patrick Apr 21; common-law rights cover early stage.
A7: Optional USPTO comprehensive search | B7: 0 | C7: 500 | D7: Gerben Law or equivalent. DEFERRED with TM filing.
A8: Domain shutterfind.app | B8: 20 | C8: 25 | D8: Cloudflare Registrar registered Apr 29 (.app TLD).
A9: Domain shutter.app (optional) | B9: 0 | C9: 18 | D9: Optional — currently NOT registered.
A10: Business insurance (GL + E&O, 6 mo prorate) | B10: 0 | C10: 360 | D10: Recommend before first real booking.
A11: Accounting / bookkeeping (DIY via Mercury) | B11: 0 | C11: 0 | D11: —
A12: Infra (Netlify + Supabase + Resend + Mapbox + GitHub) | B12: 0 | C12: 0 | D12: Free tiers through ~100 creators.
A13: D-U-N-S number | B13: 0 | C13: 0 | D13: Free for future App Store enrollment.
A14: Apple Developer Program | B14: 0 | C14: 99 | D14: $99/yr. HOLD until LLC + Stripe E2E green.
A15: Registered agent (Northwest Reg. Agent) | B15: 0 | C15: 125 | D15: Optional — Patrick can self-serve free at Truckee address.
A16: Marketing IRL print (stickers — Stickermule) | B16: 30 | C16: 30 | D16: NEW Apr 30 — $0 paid-media but real expense. Tag: marketing_irl_print.
A17: YEAR-1 NO-REVENUE TOTAL | B17: =SUM(B5:B16) -> 940 | C17: =SUM(C5:C16) -> 2547 | D17: Realistic range $2,000–$2,800 incl. trademark deferral resolution.
A20: CA FTB $800 — TIMING WINDOW
A21: Trigger: | B21: 15th day of 4th month after LLC formation date
A22: If Patrick files LLC-1 May 1, 2026 → | B22: Approval ~May 6 → FTB $800 due Aug 15, 2026
A23: If Patrick files LLC-1 May 15, 2026 → | B23: Approval ~May 22 → FTB $800 due Sep 15, 2026
A24: Patrick must budget $800 for Q3 2026 — set aside in Mercury:legal_filing_reserve sub-account.
A26: PAID-MEDIA CONTINGENCY (off-P&L until 6-precondition gate clears)
A27: Monthly cap | B27: 500 | D27: Mercury debit card per-card spend cap enforces hard ceiling.
A28: Annualized worst-case (12 mo) | B28: =B27*12 -> 6000
A29: Realistic exposure (3 mo before revenue offset) | B29: =B27*3 -> 1500
A30: Geo-ads launch gate (6 preconditions, Marketing Apr 29):
A31: ✅ Custom domain live (shutterfind.app — Apr 29)
A32: ✅ Stripe webhook live (Apr 21)
A33: ✅ Legal mark-usage sign-off (Apr 28)
A34: ⏳ 15 real creators (currently 0 / 7 seeded)
A35: ⏳ Pixels installed
A36: ⏳ SB-478 fee disclosure verified (Dev to screenshot test-mode checkout)
A37: ⏳ Brand handle claimed + 1 organic post (@shutterapp / @shutterfind)
